Workbook

Sheet trans
A1: nu | B1: unc | C1: unc | D1: Stat | E1: F | F1: e/f | G1: v | H1: J' | I1: State | J1: F" | K1: e/f" | L1: v" | M1: J" | N1: source | O1: TAG' | P1: TAG" | Q1: E' | R1: E" | S1: Esum | T1: Nsum | U1: Eave | V1: 0.5
A2: 13357.77 | B2: 0.03077 | C2: 0.03077 | D2: A | E2: 1 | F2: e | G2: 0 | H2: 0.5 | I2: X | J2: 2 | K2: f | L2: 0 | M2: 0.5 | N2: 33WaFrXx.258 | O2: =D2&"-"&E2&"-"&F2&"-"&G2&"-"&H2 -> A-1-e-0-0.5 | P2: =I2&"-"&J2&"-"&K2&"-"&L2&"-"&M2 -> X-2-f-0-0.5 | Q2: =A2+R2 -> 13364.912 | R2: =_xlfn.IFNA(VLOOKUP(P2,PGOPHER!A$2:G$181,7,FALSE),_xlfn.IFNA(VLOOKUP(P2,en!A$2:I$768,7,FALSE),-10000)) -> 7.142378 | S2: =IF(O2=O1,Q1+S1,Q2) -> 13364.912 | T2: =IF(O2=O1,T1+1,1) -> 1 | U2: =IF(O2=O3,"",S2/T2) | V2: =IF(U2="","",IF(ABS(Q2-U2)>V$1,"error",""))
A3: 13357.64 | B3: 0.03077 | C3: 0.03077 | D3: A | E3: 1 | F3: e | G3: 0 | H3: 0.5 | I3: X | J3: 1 | K3: e | L3: 0 | M3: 1.5 | N3: 33WaFrXx.220 | O3: =D3&"-"&E3&"-"&F3&"-"&G3&"-"&H3 -> A-1-e-0-0.5 | P3: =I3&"-"&J3&"-"&K3&"-"&L3&"-"&M3 -> X-1-e-0-1.5 | Q3: =A3+R3 -> 13364.968 | R3: =_xlfn.IFNA(VLOOKUP(P3,PGOPHER!A$2:G$181,7,FALSE),_xlfn.IFNA(VLOOKUP(P3,en!A$2:I$768,7,FALSE),-10000)) -> 7.328329 | S3: =IF(O3=O2,Q2+S2,Q3) -> 26729.825 | T3: =IF(O3=O2,T2+1,1) -> 2 | U3: =IF(O3=O4,"",S3/T3) -> 13364.912 | V3: =IF(U3="","",IF(ABS(Q3-U3)>V$1,"error",""))
A4: 13339.43 | B4: 0.09344 | C4: 0.09344 | D4: A | E4: 1 | F4: f | G4: 0 | H4: 0.5 | I4: X | J4: 2 | K4: f | L4: 0 | M4: 1.5 | N4: 33WaFrXx.196 | O4: =D4&"-"&E4&"-"&F4&"-"&G4&"-"&H4 -> A-1-f-0-0.5 | P4: =I4&"-"&J4&"-"&K4&"-"&L4&"-"&M4 -> X-2-f-0-1.5 | Q4: =A4+R4 -> 13361.04 | R4: =_xlfn.IFNA(VLOOKUP(P4,PGOPHER!A$2:G$181,7,FALSE),_xlfn.IFNA(VLOOKUP(P4,en!A$2:I$768,7,FALSE),-10000)) -> 21.609896 | S4: =IF(O4=O3,Q3+S3,Q4) -> 13361.04 | T4: =IF(O4=O3,T3+1,1) -> 1 | U4: =IF(O4=O5,"",S4/T4) | V4: =IF(U4="","",IF(ABS(Q4-U4)>V$1,"error",""))
A5: 13360.87 | B5: 0.09344 | C5: 0.09344 | D5: A | E5: 1 | F5: f | G5: 0 | H5: 0.5 | I5: X | J5: 1 | K5: e | L5: 0 | M5: 0.5 | N5: 33WaFrXx.293 | O5: =D5&"-"&E5&"-"&F5&"-"&G5&"-"&H5 -> A-1-f-0-0.5 | P5: =I5&"-"&J5&"-"&K5&"-"&L5&"-"&M5 -> X-1-e-0-0.5 | Q5: =A5+R5 -> 13360.87 | R5: =_xlfn.IFNA(VLOOKUP(P5,PGOPHER!A$2:G$181,7,FALSE),_xlfn.IFNA(VLOOKUP(P5,en!A$2:I$768,7,FALSE),-10000)) -> 0 | S5: =IF(O5=O4,Q4+S4,Q5) -> 26722.08 | T5: =IF(O5=O4,T4+1,1) -> 2 | U5: =IF(O5=O6,"",S5/T5) -> 13361.04 | V5: =IF(U5="","",IF(ABS(Q5-U5)>V$1,"error",""))
A6: 13356.07 | B6: 0.01246 | C6: 0.01246 | D6: A | E6: 1 | F6: e | G6: 0 | H6: 1.5 | I6: X | J6: 1 | K6: e | L6: 0 | M6: 2.5 | N6: 33WaFrXx.221 | O6: =D6&"-"&E6&"-"&F6&"-"&G6&"-"&H6 -> A-1-e-0-1.5 | P6: =I6&"-"&J6&"-"&K6&"-"&L6&"-"&M6 -> X-1-e-0-2.5 | Q6: =A6+R6 -> 13377.99 | R6: =_xlfn.IFNA(VLOOKUP(P6,PGOPHER!A$2:G$181,7,FALSE),_xlfn.IFNA(VLOOKUP(P6,en!A$2:I$768,7,FALSE),-10000)) -> 21.9197 | S6: =IF(O6=O5,Q5+S5,Q6) -> 13377.99 | T6: =IF(O6=O5,T5+1,1) -> 1 | U6: =IF(O6=O7,"",S6/T6) | V6: =IF(U6="","",IF(ABS(Q6-U6)>V$1,"error",""))
A7: 13377.83 | B7: 0.1641 | C7: 0.1641 | D7: A | E7: 1 | F7: e | G7: 0 | H7: 1.5 | I7: X | J7: 1 | K7: e | L7: 0 | M7: 0.5 | N7: 33WaFrXx.380 | O7: =D7&"-"&E7&"-"&F7&"-"&G7&"-"&H7 -> A-1-e-0-1.5 | P7: =I7&"-"&J7&"-"&K7&"-"&L7&"-"&M7 -> X-1-e-0-0.5 | Q7: =A7+R7 -> 13377.83 | R7: =_xlfn.IFNA(VLOOKUP(P7,PGOPHER!A$2:G$181,7,FALSE),_xlfn.IFNA(VLOOKUP(P7,en!A$2:I$768,7,FALSE),-10000)) -> 0 | S7: =IF(O7=O6,Q6+S6,Q7) -> 26755.979 | T7: =IF(O7=O6,T6+1,1) -> 2 | U7: =IF(O7=O8,"",S7/T7) | V7: =IF(U7="","",IF(ABS(Q7-U7)>V$1,"error",""))
A8: 13356.36 | B8: 0.01 | C8: 0.01 | D8: A | E8: 1 | F8: e | G8: 0 | H8: 1.5 | I8: X | J8: 2 | K8: f | L8: 0 | M8: 1.5 | N8: 33WaFrXx.259 | O8: =D8&"-"&E8&"-"&F8&"-"&G8&"-"&H8 -> A-1-e-0-1.5 | P8: =I8&"-"&J8&"-"&K8&"-"&L8&"-"&M8 -> X-2-f-0-1.5 | Q8: =A8+R8 -> 13377.97 | R8: =_xlfn.IFNA(VLOOKUP(P8,PGOPHER!A$2:G$181,7,FALSE),_xlfn.IFNA(VLOOKUP(P8,en!A$2:I$768,7,FALSE),-10000)) -> 21.609896 | S8: =IF(O8=O7,Q7+S7,Q8) -> 40133.809 | T8: =IF(O8=O7,T7+1,1) -> 3 | U8: =IF(O8=O9,"",S8/T8) -> 13377.936 | V8: =IF(U8="","",IF(ABS(Q8-U8)>V$1,"error",""))
A9: 13362.5 | B9: 0.1686 | C9: 0.1686 | D9: A | E9: 1 | F9: f | G9: 0 | H9: 1.5 | I9: X | J9: 2 | K9: f | L9: 0 | M9: 0.5 | N9: 33WaFrXx.339 | O9: =D9&"-"&E9&"-"&F9&"-"&G9&"-"&H9 -> A-1-f-0-1.5 | P9: =I9&"-"&J9&"-"&K9&"-"&L9&"-"&M9 -> X-2-f-0-0.5 | Q9: =A9+R9 -> 13369.642 | R9: =_xlfn.IFNA(VLOOKUP(P9,PGOPHER!A$2:G$181,7,FALSE),_xlfn.IFNA(VLOOKUP(P9,en!A$2:I$768,7,FALSE),-10000)) -> 7.142378 | S9: =IF(O9=O8,Q8+S8,Q9) -> 13369.642 | T9: =IF(O9=O8,T8+1,1) -> 1 | U9: =IF(O9=O10,"",S9/T9) | V9: =IF(U9="","",IF(ABS(Q9-U9)>V$1,"error",""))
A10: 13362.5 | B10: 0.04417 | C10: 0.04417 | D10: A | E10: 1 | F10: f | G10: 0 | H10: 1.5 | I10: X | J10: 1 | K10: e | L10: 0 | M10: 1.5 | N10: 33WaFrXx.294 | O10: =D10&"-"&E10&"-"&F10&"-"&G10&"-"&H10 -> A-1-f-0-1.5 | P10: =I10&"-"&J10&"-"&K10&"-"&L10&"-"&M10 -> X-1-e-0-1.5 | Q10: =A10+R10 -> 13369.828 | R10: =_xlfn.IFNA(VLOOKUP(P10,PGOPHER!A$2:G$181,7,FALSE),_xlfn.IFNA(VLOOKUP(P10,en!A$2:I$768,7,FALSE),-10000)) -> 7.328329 | S10: =IF(O10=O9,Q9+S9,Q10) -> 26739.285 | T10: =IF(O10=O9,T9+1,1) -> 2 | U10: =IF(O10=O11,"",S10/T10) | V10: =IF(U10="","",IF(ABS(Q10-U10)>V$1,"error",""))
A11: 13326.43 | B11: 0.035 | C11: 0.035 | D11: A | E11: 1 | F11: f | G11: 0 | H11: 1.5 | I11: X | J11: 2 | K11: f | L11: 0 | M11: 2.5 | N11: 33WaFrXx.197 | O11: =D11&"-"&E11&"-"&F11&"-"&G11&"-"&H11 -> A-1-f-0-1.5 | P11: =I11&"-"&J11&"-"&K11&"-"&L11&"-"&M11 -> X-2-f-0-2.5 | Q11: =A11+R11 -> 13369.763 | R11: =_xlfn.IFNA(VLOOKUP(P11,PGOPHER!A$2:G$181,7,FALSE),_xlfn.IFNA(VLOOKUP(P11,en!A$2:I$768,7,FALSE),-10000)) -> 43.333493 | S11: =IF(O11=O10,Q10+S10,Q11) -> 40109.113 | T11: =IF(O11=O10,T10+1,1) -> 3 | U11: =IF(O11=O12,"",S11/T11) -> 13369.704 | V11: =IF(U11="","",IF(ABS(Q11-U11)>V$1,"error",""))
A12: 13644.83 | B12: 0.07161 | C12: 0.07161 | D12: A | E12: 2 | F12: e | G12: 0 | H12: 1.5 | I12: X | J12: 2 | K12: f | L12: 0 | M12: 1.5 | N12: 33WaFrXx.48 | O12: =D12&"-"&E12&"-"&F12&"-"&G12&"-"&H12 -> A-2-e-0-1.5 | P12: =I12&"-"&J12&"-"&K12&"-"&L12&"-"&M12 -> X-2-f-0-1.5 | Q12: =A12+R12 -> 13666.44 | R12: =_xlfn.IFNA(VLOOKUP(P12,PGOPHER!A$2:G$181,7,FALSE),_xlfn.IFNA(VLOOKUP(P12,en!A$2:I$768,7,FALSE),-10000)) -> 21.609896 | S12: =IF(O12=O11,Q11+S11,Q12) -> 13666.44 | T12: =IF(O12=O11,T11+1,1) -> 1 | U12: =IF(O12=O13,"",S12/T12) | V12: =IF(U12="","",IF(ABS(Q12-U12)>V$1,"error",""))
A13: 13644.39 | B13: 0.07161 | C13: 0.07161 | D13: A | E13: 2 | F13: e | G13: 0 | H13: 1.5 | I13: X | J13: 1 | K13: e | L13: 0 | M13: 2.5 | N13: 33WaFrXx.27 | O13: =D13&"-"&E13&"-"&F13&"-"&G13&"-"&H13 -> A-2-e-0-1.5 | P13: =I13&"-"&J13&"-"&K13&"-"&L13&"-"&M13 -> X-1-e-0-2.5 | Q13: =A13+R13 -> 13666.31 | R13: =_xlfn.IFNA(VLOOKUP(P13,PGOPHER!A$2:G$181,7,FALSE),_xlfn.IFNA(VLOOKUP(P13,en!A$2:I$768,7,FALSE),-10000)) -> 21.9197 | S13: =IF(O13=O12,Q12+S12,Q13) -> 27332.88 | T13: =IF(O13=O12,T12+1,1) -> 2 | U13: =IF(O13=O14,"",S13/T13) -> 13666.44 | V13: =IF(U13="","",IF(ABS(Q13-U13)>V$1,"error",""))
... A986: 19090.182 | B986: 0.005 | C986: 0.005 | D986: E | E986: 2 | F986: f | G986: 0 | H986: 16.5 | I986: X | J986: 1 | K986: e | L986: 0 | M986: 16.5 | N986: 11RaTeWa.SrH-435 | O986: =D986&"-"&E986&"-"&F986&"-"&G986&"-"&H986 -> E-2-f-0-16.5 | P986: =I986&"-"&J986&"-"&K986&"-"&L986&"-"&M986 -> X-1-e-0-16.5 | Q986: =A986+R986 -> 20069.49 | R986: =_xlfn.IFNA(VLOOKUP(P986,PGOPHER!A$2:G$181,7,FALSE),_xlfn.IFNA(VLOOKUP(P986,en!A$2:I$768,7,FALSE),-10000)) -> 979.30796 | S986: =IF(O986=O985,Q985+S985,Q986) -> 60208.451 | T986: =IF(O986=O985,T985+1,1) -> 3 | U986: =IF(O986=O987,"",S986/T986) -> 20069.484 | V986: =IF(U986="","",IF(ABS(Q986-U986)>V$1,"error",""))
A987: 19078.148 | B987: 0.01162 | C987: 0.01162 | D987: E | E987: 2 | F987: f | G987: 1 | H987: 16.5 | I987: X | J987: 2 | K987: f | L987: 1 | M987: 15.5 | N987: 11RaTeWa.SrH-156 | S987: =IF(O987=O986,Q986+S986,Q987) -> 0 | T987: =IF(O987=O986,T986+1,1) -> 1 | U987: =IF(O987=O988,"",S987/T987) | V987: =IF(U987="","",IF(ABS(Q987-U987)>V$1,"error",""))
A988: 18835.267 | B988: 0.005 | C988: 0.005 | D988: E | E988: 2 | F988: f | G988: 1 | H988: 16.5 | I988: X | J988: 2 | K988: f | L988: 1 | M988: 17.5 | N988: 11RaTeWa.SrH-173 | S988: =IF(O988=O987,Q987+S987,Q988) -> 0 | T988: =IF(O988=O987,T987+1,1) -> 2 | U988: =IF(O988=O989,"",S988/T988) | V988: =IF(U988="","",IF(ABS(Q988-U988)>V$1,"error",""))
A989: 18958.433 | B989: 0.005 | C989: 0.005 | D989: E | E989: 2 | F989: e | G989: 1 | H989: 16.5 | I989: X | J989: 2 | K989: f | L989: 1 | M989: 16.5 | N989: 11RaTeWa.SrH-123 | S989: =IF(O989=O988,Q988+S988,Q989) -> 0 | T989: =IF(O989=O988,T988+1,1) -> 3 | U989: =IF(O989=O990,"",S989/T989) | V989: =IF(U989="","",IF(ABS(Q989-U989)>V$1,"error",""))
A990: 19076.212 | B990: 0.005 | C990: 0.005 | D990: E | E990: 2 | F990: f | G990: 1 | H990: 16.5 | I990: X | J990: 1 | K990: e | L990: 1 | M990: 16.5 | N990: 11RaTeWa.SrH-139 | S990: =IF(O990=O989,Q989+S989,Q990) -> 0 | T990: =IF(O990=O989,T989+1,1) -> 4 | U990: =IF(O990=O991,"",S990/T990) -> 0 | V990: =IF(U990="","",IF(ABS(Q990-U990)>V$1,"error",""))
A991: 19046.977 | B991: 0.005 | C991: 0.005 | D991: E | E991: 1 | F991: e | G991: 0 | H991: 17.5 | I991: X | J991: 1 | K991: e | L991: 0 | M991: 16.5 | N991: 11RaTeWa.SrH-190 | O991: =D991&"-"&E991&"-"&F991&"-"&G991&"-"&H991 -> E-1-e-0-17.5 | P991: =I991&"-"&J991&"-"&K991&"-"&L991&"-"&M991 -> X-1-e-0-16.5 | Q991: =A991+R991 -> 20026.285 | R991: =_xlfn.IFNA(VLOOKUP(P991,PGOPHER!A$2:G$181,7,FALSE),_xlfn.IFNA(VLOOKUP(P991,en!A$2:I$768,7,FALSE),-10000)) -> 979.30796 | S991: =IF(O991=O990,Q990+S990,Q991) -> 20026.285 | T991: =IF(O991=O990,T990+1,1) -> 1 | U991: =IF(O991=O992,"",S991/T991) | V991: =IF(U991="","",IF(ABS(Q991-U991)>V$1,"error",""))
A992: 18798.274 | B992: 0.005 | C992: 0.005 | D992: E | E992: 1 | F992: e | G992: 0 | H992: 17.5 | I992: X | J992: 1 | K992: e | L992: 0 | M992: 18.5 | N992: 11RaTeWa.SrH-221 | O992: =D992&"-"&E992&"-"&F992&"-"&G992&"-"&H992 -> E-1-e-0-17.5 | P992: =I992&"-"&J992&"-"&K992&"-"&L992&"-"&M992 -> X-1-e-0-18.5 | Q992: =A992+R992 -> 20026.283 | R992: =_xlfn.IFNA(VLOOKUP(P992,PGOPHER!A$2:G$181,7,FALSE),_xlfn.IFNA(VLOOKUP(P992,en!A$2:I$768,7,FALSE),-10000)) -> 1228.0093 | S992: =IF(O992=O991,Q991+S991,Q992) -> 40052.569 | T992: =IF(O992=O991,T991+1,1) -> 2 | U992: =IF(O992=O993,"",S992/T992) | V992: =IF(U992="","",IF(ABS(Q992-U992)>V$1,"error",""))
A993: 18800.492 | B993: 0.005 | C993: 0.005 | D993: E | E993: 1 | F993: e | G993: 0 | H993: 17.5 | I993: X | J993: 2 | K993: f | L993: 0 | M993: 17.5 | N993: 11RaTeWa.SrH-250 | O993: =D993&"-"&E993&"-"&F993&"-"&G993&"-"&H993 -> E-1-e-0-17.5 | P993: =I993&"-"&J993&"-"&K993&"-"&L993&"-"&M993 -> X-2-f-0-17.5 | Q993: =A993+R993 -> 20026.281 | R993: =_xlfn.IFNA(VLOOKUP(P993,PGOPHER!A$2:G$181,7,FALSE),_xlfn.IFNA(VLOOKUP(P993,en!A$2:I$768,7,FALSE),-10000)) -> 1225.7899 | S993: =IF(O993=O992,Q992+S992,Q993) -> 60078.852 | T993: =IF(O993=O992,T992+1,1) -> 3 | U993: =IF(O993=O994,"",S993/T993) -> 20026.284 | V993: =IF(U993="","",IF(ABS(Q993-U993)>V$1,"error",""))
A994: 18925.177 | B994: 0.005 | C994: 0.005 | D994: E | E994: 1 | F994: f | G994: 0 | H994: 17.5 | I994: X | J994: 1 | K994: e | L994: 0 | M994: 17.5 | N994: 11RaTeWa.SrH-304 | O994: =D994&"-"&E994&"-"&F994&"-"&G994&"-"&H994 -> E-1-f-0-17.5 | P994: =I994&"-"&J994&"-"&K994&"-"&L994&"-"&M994 -> X-1-e-0-17.5 | Q994: =A994+R994 -> 20025.449 | R994: =_xlfn.IFNA(VLOOKUP(P994,PGOPHER!A$2:G$181,7,FALSE),_xlfn.IFNA(VLOOKUP(P994,en!A$2:I$768,7,FALSE),-10000)) -> 1100.272 | S994: =IF(O994=O993,Q993+S993,Q994) -> 20025.449 | T994: =IF(O994=O993,T993+1,1) -> 1 | U994: =IF(O994=O995,"",S994/T994) | V994: =IF(U994="","",IF(ABS(Q994-U994)>V$1,"error",""))
A995: 18665.297 | B995: 0.025 | C995: 0.025 | D995: E | E995: 1 | F995: f | G995: 0 | H995: 17.5 | I995: X | J995: 2 | K995: f | L995: 0 | M995: 18.5 | N995: 11RaTeWa.SrH-272 | O995: =D995&"-"&E995&"-"&F995&"-"&G995&"-"&H995 -> E-1-f-0-17.5 | P995: =I995&"-"&J995&"-"&K995&"-"&L995&"-"&M995 -> X-2-f-0-18.5 | Q995: =A995+R995 -> 20025.442 | R995: =_xlfn.IFNA(VLOOKUP(P995,PGOPHER!A$2:G$181,7,FALSE),_xlfn.IFNA(VLOOKUP(P995,en!A$2:I$768,7,FALSE),-10000)) -> 1360.1445 | S995: =IF(O995=O994,Q994+S994,Q995) -> 40050.898 | T995: =IF(O995=O994,T994+1,1) -> 2 | U995: =IF(O995=O996,"",S995/T995) -> 20025.449 | V995: =IF(U995="","",IF(ABS(Q995-U995)>V$1,"error",""))
A996: 18972.568 | B996: 0.005 | C996: 0.005 | D996: E | E996: 2 | F996: e | G996: 0 | H996: 17.5 | I996: X | J996: 2 | K996: f | L996: 0 | M996: 17.5 | N996: 11RaTeWa.SrH-355 | O996: =D996&"-"&E996&"-"&F996&"-"&G996&"-"&H996 -> E-2-e-0-17.5 | P996: =I996&"-"&J996&"-"&K996&"-"&L996&"-"&M996 -> X-2-f-0-17.5 | Q996: =A996+R996 -> 20198.358 | R996: =_xlfn.IFNA(VLOOKUP(P996,PGOPHER!A$2:G$181,7,FALSE),_xlfn.IFNA(VLOOKUP(P996,en!A$2:I$768,7,FALSE),-10000)) -> 1225.7899 | S996: =IF(O996=O995,Q995+S995,Q996) -> 20198.358 | T996: =IF(O996=O995,T995+1,1) -> 1 | U996: =IF(O996=O997,"",S996/T996) | V996: =IF(U996="","",IF(ABS(Q996-U996)>V$1,"error",""))
A997: 19219.043 | B997: 0.005 | C997: 0.005 | D997: E | E997: 2 | F997: e | G997: 0 | H997: 17.5 | I997: X | J997: 1 | K997: e | L997: 0 | M997: 16.5 | N997: 11RaTeWa.SrH-327 | O997: =D997&"-"&E997&"-"&F997&"-"&G997&"-"&H997 -> E-2-e-0-17.5 | P997: =I997&"-"&J997&"-"&K997&"-"&L997&"-"&M997 -> X-1-e-0-16.5 | Q997: =A997+R997 -> 20198.351 | R997: =_xlfn.IFNA(VLOOKUP(P997,PGOPHER!A$2:G$181,7,FALSE),_xlfn.IFNA(VLOOKUP(P997,en!A$2:I$768,7,FALSE),-10000)) -> 979.30796 | S997: =IF(O997=O996,Q996+S996,Q997) -> 40396.715 | T997: =IF(O997=O996,T996+1,1) -> 2 | U997: =IF(O997=O998,"",S997/T997) -> 20198.358 | V997: =IF(U997="","",IF(ABS(Q997-U997)>V$1,"error",""))
A998: 19102.493 | B998: 0.005 | C998: 0.005 | D998: E | E998: 2 | F998: f | G998: 0 | H998: 17.5 | I998: X | J998: 2 | K998: f | L998: 0 | M998: 16.5 | N998: 11RaTeWa.SrH-383 | O998: =D998&"-"&E998&"-"&F998&"-"&G998&"-"&H998 -> E-2-f-0-17.5 | P998: =I998&"-"&J998&"-"&K998&"-"&L998&"-"&M998 -> X-2-f-0-16.5 | Q998: =A998+R998 -> 20200.658 | R998: =_xlfn.IFNA(VLOOKUP(P998,PGOPHER!A$2:G$181,7,FALSE),_xlfn.IFNA(VLOOKUP(P998,en!A$2:I$768,7,FALSE),-10000)) -> 1098.165 | S998: =IF(O998=O997,Q997+S997,Q998) -> 20200.658 | T998: =IF(O998=O997,T997+1,1) -> 1 | U998: =IF(O998=O999,"",S998/T998) | V998: =IF(U998="","",IF(ABS(Q998-U998)>V$1,"error",""))
A999: 18840.507 | B999: 0.005 | C999: 0.005 | D999: E | E999: 2 | F999: f | G999: 0 | H999: 17.5 | I999: X | J999: 2 | K999: f | L999: 0 | M999: 18.5 | N999: 11RaTeWa.SrH-412 | O999: =D999&"-"&E999&"-"&F999&"-"&G999&"-"&H999 -> E-2-f-0-17.5 | P999: =I999&"-"&J999&"-"&K999&"-"&L999&"-"&M999 -> X-2-f-0-18.5 | Q999: =A999+R999 -> 20200.651 | R999: =_xlfn.IFNA(VLOOKUP(P999,PGOPHER!A$2:G$181,7,FALSE),_xlfn.IFNA(VLOOKUP(P999,en!A$2:I$768,7,FALSE),-10000)) -> 1360.1445 | S999: =IF(O999=O998,Q998+S998,Q999) -> 40401.316 | T999: =IF(O999=O998,T998+1,1) -> 2 | U999: =IF(O999=O1000,"",S999/T999) | V999: =IF(U999="","",IF(ABS(Q999-U999)>V$1,"error",""))
A1000: 19100.385 | B1000: 0.005 | C1000: 0.005 | D1000: E | E1000: 2 | F1000: f | G1000: 0 | H1000: 17.5 | I1000: X | J1000: 1 | K1000: e | L1000: 0 | M1000: 17.5 | N1000: 11RaTeWa.SrH-436 | O1000: =D1000&"-"&E1000&"-"&F1000&"-"&G1000&"-"&H1000 -> E-2-f-0-17.5 | P1000: =I1000&"-"&J1000&"-"&K1000&"-"&L1000&"-"&M1000 -> X-1-e-0-17.5 | Q1000: =A1000+R1000 -> 20200.657 | R1000: =_xlfn.IFNA(VLOOKUP(P1000,PGOPHER!A$2:G$181,7,FALSE),_xlfn.IFNA(VLOOKUP(P1000,en!A$2:I$768,7,FALSE),-10000)) -> 1100.272 | S1000: =IF(O1000=O999,Q999+S999,Q1000) -> 60601.967 | T1000: =IF(O1000=O999,T999+1,1) -> 3 | U1000: =IF(O1000=O1001,"",S1000/T1000) -> 20200.656 | V1000: =IF(U1000="","",IF(ABS(Q1000-U1000)>V$1,"error",""))
A1001: 19087.395 | B1001: 0.005 | C1001: 0.005 | D1001: E | E1001: 2 | F1001: f | G1001: 1 | H1001: 17.5 | I1001: X | J1001: 2 | K1001: f | L1001: 1 | M1001: 16.5 | N1001: 11RaTeWa.SrH-157 | S1001: =IF(O1001=O1000,Q1000+S1000,Q1001) -> 0 | T1001: =IF(O1001=O1000,T1000+1,1) -> 1 | U1001: =IF(O1001=O1002,"",S1001/T1001) | V1001: =IF(U1001="","",IF(ABS(Q1001-U1001)>V$1,"error",""))
A1002: 18831.334 | B1002: 0.00608 | C1002: 0.00608 | D1002: E | E1002: 2 | F1002: f | G1002: 1 | H1002: 17.5 | I1002: X | J1002: 2 | K1002: f | L1002: 1 | M1002: 18.5 | N1002: 11RaTeWa.SrH-174 | S1002: =IF(O1002=O1001,Q1001+S1001,Q1002) -> 0 | T1002: =IF(O1002=O1001,T1001+1,1) -> 2 | U1002: =IF(O1002=O1003,"",S1002/T1002) | V1002: =IF(U1002="","",IF(ABS(Q1002-U1002)>V$1,"error",""))
A1003: 18786.934 | B1003: 0.005 | C1003: 0.005 | D1003: E | E1003: 1 | F1003: e | G1003: 1 | H1003: 17.5 | I1003: X | J1003: 1 | K1003: e | L1003: 1 | M1003: 18.5 | N1003: 11RaTeWa.SrH-17 | S1003: =IF(O1003=O1002,Q1002+S1002,Q1003) -> 0 | T1003: =IF(O1003=O1002,T1002+1,1) -> 3 | U1003: =IF(O1003=O1004,"",S1003/T1003) | V1003: =IF(U1003="","",IF(ABS(Q1003-U1003)>V$1,"error",""))
A1004: 19030.034 | B1004: 0.005 | C1004: 0.005 | D1004: E | E1004: 1 | F1004: e | G1004: 1 | H1004: 17.5 | I1004: X | J1004: 1 | K1004: e | L1004: 1 | M1004: 16.5 | N1004: 11RaTeWa.SrH-34 | S1004: =IF(O1004=O1003,Q1003+S1003,Q1004) -> 0 | T1004: =IF(O1004=O1003,T1003+1,1) -> 4 | U1004: =IF(O1004=O1005,"",S1004/T1004) | V1004: =IF(U1004="","",IF(ABS(Q1004-U1004)>V$1,"error",""))
A1005: 18911.138 | B1005: 0.105 | C1005: 0.105 | D1005: E | E1005: 1 | F1005: f | G1005: 1 | H1005: 17.5 | I1005: X | J1005: 1 | K1005: e | L1005: 1 | M1005: 17.5 | N1005: 11RaTeWa.SrH-81 | S1005: =IF(O1005=O1004,Q1004+S1004,Q1005) -> 0 | T1005: =IF(O1005=O1004,T1004+1,1) -> 5 | U1005: =IF(O1005=O1006,"",S1005/T1005) | V1005: =IF(U1005="","",IF(ABS(Q1005-U1005)>V$1,"error",""))
A1006: 18960.932 | B1006: 0.005 | C1006: 0.005 | D1006: E | E1006: 2 | F1006: e | G1006: 1 | H1006: 17.5 | I1006: X | J1006: 2 | K1006: f | L1006: 1 | M1006: 17.5 | N1006: 11RaTeWa.SrH-124 | S1006: =IF(O1006=O1005,Q1005+S1005,Q1006) -> 0 | T1006: =IF(O1006=O1005,T1005+1,1) -> 6 | U1006: =IF(O1006=O1007,"",S1006/T1006) | V1006: =IF(U1006="","",IF(ABS(Q1006-U1006)>V$1,"error",""))
A1007: 19085.363 | B1007: 0.00594 | C1007: 0.00594 | D1007: E | E1007: 2 | F1007: f | G1007: 1 | H1007: 17.5 | I1007: X | J1007: 1 | K1007: e | L1007: 1 | M1007: 17.5 | N1007: 11RaTeWa.SrH-140 | S1007: =IF(O1007=O1006,Q1006+S1006,Q1007) -> 0 | T1007: =IF(O1007=O1006,T1006+1,1) -> 7 | U1007: =IF(O1007=O1008,"",S1007/T1007) -> 0 | V1007: =IF(U1007="","",IF(ABS(Q1007-U1007)>V$1,"error",""))
A1008: 19058.181 | B1008: 0.005 | C1008: 0.005 | D1008: E | E1008: 1 | F1008: e | G1008: 0 | H1008: 18.5 | I1008: X | J1008: 1 | K1008: e | L1008: 0 | M1008: 17.5 | N1008: 11RaTeWa.SrH-191 | O1008: =D1008&"-"&E1008&"-"&F1008&"-"&G1008&"-"&H1008 -> E-1-e-0-18.5 | P1008: =I1008&"-"&J1008&"-"&K1008&"-"&L1008&"-"&M1008 -> X-1-e-0-17.5 | Q1008: =A1008+R1008 -> 20158.453 | R1008: =_xlfn.IFNA(VLOOKUP(P1008,PGOPHER!A$2:G$181,7,FALSE),_xlfn.IFNA(VLOOKUP(P1008,en!A$2:I$768,7,FALSE),-10000)) -> 1100.272 | S1008: =IF(O1008=O1007,Q1007+S1007,Q1008) -> 20158.453 | T1008: =IF(O1008=O1007,T1007+1,1) -> 1 | U1008: =IF(O1008=O1009,"",S1008/T1008) | V1008: =IF(U1008="","",IF(ABS(Q1008-U1008)>V$1,"error",""))
A1009: 18795.972 | B1009: 0.006553 | C1009: 0.006553 | D1009: E | E1009: 1 | F1009: e | G1009: 0 | H1009: 18.5 | I1009: X | J1009: 1 | K1009: e | L1009: 0 | M1009: 19.5 | N1009: 11RaTeWa.SrH-222 | O1009: =D1009&"-"&E1009&"-"&F1009&"-"&G1009&"-"&H1009 -> E-1-e-0-18.5 | P1009: =I1009&"-"&J1009&"-"&K1009&"-"&L1009&"-"&M1009 -> X-1-e-0-19.5 | Q1009: =A1009+R1009 -> 20158.447 | R1009: =_xlfn.IFNA(VLOOKUP(P1009,PGOPHER!A$2:G$181,7,FALSE),_xlfn.IFNA(VLOOKUP(P1009,en!A$2:I$768,7,FALSE),-10000)) -> 1362.4751 | S1009: =IF(O1009=O1008,Q1008+S1008,Q1009) -> 40316.906 | T1009: =IF(O1009=O1008,T1008+1,1) -> 2 | U1009: =IF(O1009=O1010,"",S1009/T1009) | V1009: =IF(U1009="","",IF(ABS(Q1009-U1009)>V$1,"error",""))
A1010: 18798.311 | B1010: 0.005825 | C1010: 0.005825 | D1010: E | E1010: 1 | F1010: e | G1010: 0 | H1010: 18.5 | I1010: X | J1010: 2 | K1010: f | L1010: 0 | M1010: 18.5 | N1010: 11RaTeWa.SrH-251 | O1010: =D1010&"-"&E1010&"-"&F1010&"-"&G1010&"-"&H1010 -> E-1-e-0-18.5 | P1010: =I1010&"-"&J1010&"-"&K1010&"-"&L1010&"-"&M1010 -> X-2-f-0-18.5 | Q1010: =A1010+R1010 -> 20158.455 | R1010: =_xlfn.IFNA(VLOOKUP(P1010,PGOPHER!A$2:G$181,7,FALSE),_xlfn.IFNA(VLOOKUP(P1010,en!A$2:I$768,7,FALSE),-10000)) -> 1360.1445 | S1010: =IF(O1010=O1009,Q1009+S1009,Q1010) -> 60475.353 | T1010: =IF(O1010=O1009,T1009+1,1) -> 3 | U1010: =IF(O1010=O1011,"",S1010/T1010) -> 20158.451 | V1010: =IF(U1010="","",IF(ABS(Q1010-U1010)>V$1,"error",""))
A1011: 18929.383 | B1011: 0.005 | C1011: 0.005 | D1011: E | E1011: 1 | F1011: f | G1011: 0 | H1011: 18.5 | I1011: X | J1011: 1 | K1011: e | L1011: 0 | M1011: 18.5 | N1011: 11RaTeWa.SrH-305 | O1011: =D1011&"-"&E1011&"-"&F1011&"-"&G1011&"-"&H1011 -> E-1-f-0-18.5 | P1011: =I1011&"-"&J1011&"-"&K1011&"-"&L1011&"-"&M1011 -> X-1-e-0-18.5 | Q1011: =A1011+R1011 -> 20157.392 | R1011: =_xlfn.IFNA(VLOOKUP(P1011,PGOPHER!A$2:G$181,7,FALSE),_xlfn.IFNA(VLOOKUP(P1011,en!A$2:I$768,7,FALSE),-10000)) -> 1228.0093 | S1011: =IF(O1011=O1010,Q1010+S1010,Q1011) -> 20157.392 | T1011: =IF(O1011=O1010,T1010+1,1) -> 1 | U1011: =IF(O1011=O1012,"",S1011/T1011) -> 20157.392 | V1011: =IF(U1011="","",IF(ABS(Q1011-U1011)>V$1,"error",""))
A1012: 18976.047 | B1012: 0.005 | C1012: 0.005 | D1012: E | E1012: 2 | F1012: e | G1012: 0 | H1012: 18.5 | I1012: X | J1012: 2 | K1012: f | L1012: 0 | M1012: 18.5 | N1012: 11RaTeWa.SrH-356 | O1012: =D1012&"-"&E1012&"-"&F1012&"-"&G1012&"-"&H1012 -> E-2-e-0-18.5 | P1012: =I1012&"-"&J1012&"-"&K1012&"-"&L1012&"-"&M1012 -> X-2-f-0-18.5 | Q1012: =A1012+R1012 -> 20336.192 | R1012: =_xlfn.IFNA(VLOOKUP(P1012,PGOPHER!A$2:G$181,7,FALSE),_xlfn.IFNA(VLOOKUP(P1012,en!A$2:I$768,7,FALSE),-10000)) -> 1360.1445 | S1012: =IF(O1012=O1011,Q1011+S1011,Q1012) -> 20336.192 | T1012: =IF(O1012=O1011,T1011+1,1) -> 1 | U1012: =IF(O1012=O1013,"",S1012/T1012) | V1012: =IF(U1012="","",IF(ABS(Q1012-U1012)>V$1,"error",""))
...

Sheet en
A1: TAG | B1: State | D1: e/f | F1: J | G1: En | H1: unc
A2: =B2&"-"&C2&"-"&D2&"-"&E2&"-"&F2 -> X-1-e-0-0.5 | B2: X | C2: 1 | D2: e | E2: 0 | F2: 0.5 | G2: 0 | H2: 0 | I2: 21
A3: =B3&"-"&C3&"-"&D3&"-"&E3&"-"&F3 -> X-2-f-0-0.5 | B3: X | C3: 2 | D3: f | E3: 0 | F3: 0.5 | G3: 7.142378 | H3: 5e-06 | I3: 2
A4: =B4&"-"&C4&"-"&D4&"-"&E4&"-"&F4 -> X-1-e-1-0.5 | B4: X | C4: 1 | D4: e | E4: 1 | F4: 0.5 | G4: 1172.805 | H4: 0.002523 | I4: 24
A5: =B5&"-"&C5&"-"&D5&"-"&E5&"-"&F5 -> X-2-f-1-0.5 | B5: X | C5: 2 | D5: f | E5: 1 | F5: 0.5 | G5: 1179.7886 | H5: 0.001015 | I5: 3
A6: =B6&"-"&C6&"-"&D6&"-"&E6&"-"&F6 -> X-1-e-2-0.5 | B6: X | C6: 1 | D6: e | E6: 2 | F6: 0.5 | G6: 2311.4505 | H6: 0.002 | I6: 22
A7: =B7&"-"&C7&"-"&D7&"-"&E7&"-"&F7 -> X-2-f-2-0.5 | B7: X | C7: 2 | D7: f | E7: 2 | F7: 0.5 | G7: 2318.2805 | H7: 0.015405 | I7: 3
A8: =B8&"-"&C8&"-"&D8&"-"&E8&"-"&F8 -> X-2-f-3-0.5 | B8: X | C8: 2 | D8: f | E8: 3 | F8: 0.5 | G8: 3422.5452 | H8: 0.003015 | I8: 22
A9: =B9&"-"&C9&"-"&D9&"-"&E9&"-"&F9 -> A-1-f-0-0.5 | B9: A | C9: 1 | D9: f | E9: 0 | F9: 0.5 | G9: 13360.955 | H9: 0.093443 | I9: 3
A10: =B10&"-"&C10&"-"&D10&"-"&E10&"-"&F10 -> A-1-e-0-0.5 | B10: A | C10: 1 | D10: e | E10: 0 | F10: 0.5 | G10: 13364.94 | H10: 0.030778 | I10: 21
A11: =B11&"-"&C11&"-"&D11&"-"&E11&"-"&F11 -> B-1-e-0-0.5 | B11: B | C11: 1 | D11: e | E11: 0 | F11: 0.5 | G11: 14352.628 | H11: 0.01001 | I11: 3
A12: =B12&"-"&C12&"-"&D12&"-"&E12&"-"&F12 -> E-1-e-0-0.5 | B12: E | C12: 1 | D12: e | E12: 0 | F12: 0.5 | G12: 18864.357 | H12: 0.005005 | I12: 22
A13: =B13&"-"&C13&"-"&D13&"-"&E13&"-"&F13 -> E-1-f-0-0.5 | B13: E | C13: 1 | D13: f | E13: 0 | F13: 0.5 | G13: 18864.448 | H13: 0.005 | I13: 3
... A768: =B768&"-"&C768&"-"&D768&"-"&E768&"-"&F768 -> A-2-f-0-37.5 | B768: A | C768: 2 | D768: f | E768: 0 | F768: 37.5 | G768: 18698.423 | H768: 3.006469 | I768: 1

Sheet PGOPHER
A1: TAG | D1: J | E1: e/f | K1: v | P1: J | Q1: e/f | R1: n | S1: E | T1: State | U1: v
A2: ="X"&"-"&O2&"-"&Q2&"-"&K2&"-"&P2&"PG" -> X-1-e-0-0.5PG | C2: Ground | D2: 0.5 | E2: e | F2: 1 | G2: 0 | H2: 2 | I2: 0.015911634 | J2: Ground | K2: 0 | L2: 0.5 | M2: 0 | N2: F1e | O2: 1 | P2: =D2 -> 0.5 | Q2: =E2 -> e | R2: =P2+0.5+U2 -> 1 | S2: =G2 -> 0 | T2: X | U2: =K2 -> 0 | V2: 0 | W2: 0.5 | X2: 0.5 | Y2: 1
A3: ="X"&"-"&O3&"-"&Q3&"-"&K3&"-"&P3&"PG" -> X-2-f-0-0.5PG | C3: Ground | D3: 0.5 | E3: f | F3: 1 | G3: 6.5067 | H3: 2 | I3: 0.015422769 | J3: Ground | K3: 0 | L3: 0.5 | M3: 1 | N3: F2f | O3: 2 | P3: =D3 -> 0.5 | Q3: =E3 -> f | R3: =P3+0.5+U3 -> 1 | S3: =G3 -> 6.5067 | T3: X | U3: =K3 -> 0 | V3: 0 | W3: 0.5 | X3: 0.5 | Y3: 1
A4: ="X"&"-"&O4&"-"&Q4&"-"&K4&"-"&P4&"PG" -> X-1-e-0-1.5PG | C4: Ground | D4: 1.5 | E4: e | F4: 1 | G4: 6.7947 | H4: 4 | I4: 0.030802955 | J4: Ground | K4: 0 | L4: 1.5 | M4: 1 | N4: F1e | O4: 1 | P4: =D4 -> 1.5 | Q4: =E4 -> e | R4: =P4+0.5+U4 -> 2 | S4: =G4 -> 6.7947 | T4: X | U4: =K4 -> 0 | V4: 0 | W4: 0.5 | X4: 0.5 | Y4: 1
A5: ="X"&"-"&O5&"-"&Q5&"-"&K5&"-"&P5&"PG" -> X-2-f-0-1.5PG | C5: Ground | D5: 1.5 | E5: f | F5: 1 | G5: 19.8055 | H5: 4 | I5: 0.028939632 | J5: Ground | K5: 0 | L5: 1.5 | M5: 2 | N5: F2f | O5: 2 | P5: =D5 -> 1.5 | Q5: =E5 -> f | R5: =P5+0.5+U5 -> 2 | S5: =G5 -> 19.8055 | T5: X | U5: =K5 -> 0 | V5: 0 | W5: 0.5 | X5: 0.5 | Y5: 1
A6: ="X"&"-"&O6&"-"&Q6&"-"&K6&"-"&P6&"PG" -> X-1-e-0-2.5PG | C6: Ground | D6: 2.5 | E6: e | F6: 1 | G6: 20.2855 | H6: 6 | I6: 0.043309641 | J6: Ground | K6: 0 | L6: 2.5 | M6: 2 | N6: F1e | O6: 1 | P6: =D6 -> 2.5 | Q6: =E6 -> e | R6: =P6+0.5+U6 -> 3 | S6: =G6 -> 20.2855 | T6: X | U6: =K6 -> 0 | V6: 0 | W6: 0.5 | X6: 0.5 | Y6: 1
A7: ="X"&"-"&O7&"-"&Q7&"-"&K7&"-"&P7&"PG" -> X-2-f-0-2.5PG | C7: Ground | D7: 2.5 | E7: f | F7: 1 | G7: 39.7951 | H7: 6 | I7: 0.039441113 | J7: Ground | K7: 0 | L7: 2.5 | M7: 3 | N7: F2f | O7: 2 | P7: =D7 -> 2.5 | Q7: =E7 -> f | R7: =P7+0.5+U7 -> 3 | S7: =G7 -> 39.7951 | T7: X | U7: =K7 -> 0 | V7: 0 | W7: 0.5 | X7: 0.5 | Y7: 1
A8: ="X"&"-"&O8&"-"&Q8&"-"&K8&"-"&P8&"PG" -> X-1-e-0-3.5PG | C8: Ground | D8: 3.5 | E8: e | F8: 1 | G8: 40.4667 | H8: 8 | I8: 0.052419025 | J8: Ground | K8: 0 | L8: 3.5 | M8: 3 | N8: F1e | O8: 1 | P8: =D8 -> 3.5 | Q8: =E8 -> e | R8: =P8+0.5+U8 -> 4 | S8: =G8 -> 40.4667 | T8: X | U8: =K8 -> 0 | V8: 0 | W8: 0.5 | X8: 0.5 | Y8: 1
A9: ="X"&"-"&O9&"-"&Q9&"-"&K9&"-"&P9&"PG" -> X-2-f-0-3.5PG | C9: Ground | D9: 3.5 | E9: f | F9: 1 | G9: 66.4673 | H9: 8 | I9: 0.046273662 | J9: Ground | K9: 0 | L9: 3.5 | M9: 4 | N9: F2f | O9: 2 | P9: =D9 -> 3.5 | Q9: =E9 -> f | R9: =P9+0.5+U9 -> 4 | S9: =G9 -> 66.4673 | T9: X | U9: =K9 -> 0 | V9: 0 | W9: 0.5 | X9: 0.5 | Y9: 1
A10: ="X"&"-"&O10&"-"&Q10&"-"&K10&"-"&P10&"PG" -> X-1-e-0-4.5PG | C10: Ground | D10: 4.5 | E10: e | F10: 1 | G10: 67.3303 | H10: 10 | I10: 0.057603147 | J10: Ground | K10: 0 | L10: 4.5 | M10: 4 | N10: F1e | O10: 1 | P10: =D10 -> 4.5 | Q10: =E10 -> e | R10: =P10+0.5+U10 -> 5 | S10: =G10 -> 67.3303 | T10: X | U10: =K10 -> 0 | V10: 0 | W10: 0.5 | X10: 0.5 | Y10: 1
A11: ="X"&"-"&O11&"-"&Q11&"-"&K11&"-"&P11&"PG" -> X-2-f-0-4.5PG | C11: Ground | D11: 4.5 | E11: f | F11: 1 | G11: 99.8114 | H11: 10 | I11: 0.049293915 | J11: Ground | K11: 0 | L11: 4.5 | M11: 5 | N11: F2f | O11: 2 | P11: =D11 -> 4.5 | Q11: =E11 -> f | R11: =P11+0.5+U11 -> 5 | S11: =G11 -> 99.8114 | T11: X | U11: =K11 -> 0 | V11: 0 | W11: 0.5 | X11: 0.5 | Y11: 1
A12: ="X"&"-"&O12&"-"&Q12&"-"&K12&"-"&P12&"PG" -> X-1-e-0-5.5PG | C12: Ground | D12: 5.5 | E12: e | F12: 1 | G12: 100.8655 | H12: 12 | I12: 0.058854399 | J12: Ground | K12: 0 | L12: 5.5 | M12: 5 | N12: F1e | O12: 1 | P12: =D12 -> 5.5 | Q12: =E12 -> e | R12: =P12+0.5+U12 -> 6 | S12: =G12 -> 100.8655 | T12: X | U12: =K12 -> 0 | V12: 0 | W12: 0.5 | X12: 0.5 | Y12: 1
A13: ="X"&"-"&O13&"-"&Q13&"-"&K13&"-"&P13&"PG" -> X-2-f-0-5.5PG | C13: Ground | D13: 5.5 | E13: f | F13: 1 | G13: 139.814 | H13: 12 | I13: 0.048826483 | J13: Ground | K13: 0 | L13: 5.5 | M13: 6 | N13: F2f | O13: 2 | P13: =D13 -> 5.5 | Q13: =E13 -> f | R13: =P13+0.5+U13 -> 6 | S13: =G13 -> 139.814 | T13: X | U13: =K13 -> 0 | V13: 0 | W13: 0.5 | X13: 0.5 | Y13: 1
... A181: ="X"&"-"&O181&"-"&Q181&"-"&K181&"-"&P181&"PG" -> X-2-f-2-29.5PG | C181: Excited | D181: 29.5 | E181: f | F181: 2 | G181: 5145.1094 | H181: 60 | I181: 9.1702e-12 | J181: Excited | K181: 2 | L181: 29.5 | M181: 30 | N181: F2f | O181: 2 | P181: =D181 -> 29.5 | Q181: =E181 -> f | R181: =P181+0.5+U181 -> 32 | S181: =G181 -> 5145.1094 | T181: X | U181: =K181 -> 2 | V181: 0 | W181: 0.5 | X181: 0.5 | Y181: 1
